Workbook
Name Slicer_Age: #N/A
Name Slicer_Country: #N/A
Name Slicer_Overall_Impact: #N/A

Sheet Project 1
A1: TASKS — Complete the following using this dataset
A2: 1. Format the Salary column as Currency with 2 decimal places
A3: 2. Apply Bold and Dark Blue fill to the header row
A4: 3. Calculate Tax (20%) and Net Pay using formulas for all 10 employees
A5: 4. Add a Bonus column (10% of salary) using an absolute reference to a bonus rate cell
A6: 5. Use SUM at the bottom to total the Salary, Tax, Net Pay, and Bonus columns
A7: 6. Apply alternating row shading (grey/white) to the data rows
A8: 7. Resize all columns to fit content using Format > AutoFit Column Width
A10: EmpID | B10: Full Name | C10: Department | D10: Salary | E10: Tax (20%) | F10: Net Pay | G10: Bonus (10%)
A11: 1001 | B11: Jim Halpert | C11: Sales | D11: 45000 | E11: =(D11/10)*2 -> 9000 | F11: =(D11+G11-E11) -> 40500 | G11: =(D11/10) -> 4500
A12: 1002 | B12: Pam Beasley | C12: Admin | D12: 36000 | E12: =(D12/10)*2 -> 7200 | F12: =(D12+G12-E12) -> 32400 | G12: =(D12/10) -> 3600
A13: 1003 | B13: Dwight Schrute | C13: Sales | D13: 63000 | E13: =(D13/10)*2 -> 12600 | F13: =(D13+G13-E13) -> 56700 | G13: =(D13/10) -> 6300
A14: 1004 | B14: Angela Martin | C14: Accounting | D14: 47000 | E14: =(D14/10)*2 -> 9400 | F14: =(D14+G14-E14) -> 42300 | G14: =(D14/10) -> 4700
A15: 1005 | B15: Toby Flenderson | C15: HR | D15: 50000 | E15: =(D15/10)*2 -> 10000 | F15: =(D15+G15-E15) -> 45000 | G15: =(D15/10) -> 5000
A16: 1006 | B16: Michael Scott | C16: Management | D16: 65000 | E16: =(D16/10)*2 -> 13000 | F16: =(D16+G16-E16) -> 58500 | G16: =(D16/10) -> 6500
A17: 1007 | B17: Meredith Palmer | C17: Supply | D17: 55000 | E17: =(D17/10)*2 -> 11000 | F17: =(D17+G17-E17) -> 49500 | G17: =(D17/10) -> 5500
A18: 1008 | B18: Stanley Hudson | C18: Sales | D18: 48000 | E18: =(D18/10)*2 -> 9600 | F18: =(D18+G18-E18) -> 43200 | G18: =(D18/10) -> 4800
A19: 1009 | B19: Kevin Malone | C19: Accounting | D19: 52000 | E19: =(D19/10)*2 -> 10400 | F19: =(D19+G19-E19) -> 46800 | G19: =(D19/10) -> 5200
A20: 1010 | B20: Oscar Martinez | C20: Accounting | D20: 58000 | E20: =(D20/10)*2 -> 11600 | F20: =(D20+G20-E20) -> 52200 | G20: =(D20/10) -> 5800
A21: TOTAL | D21: =SUM(D11:D20) -> 519000 | E21: =SUM(E11:E20) -> 103800 | F21: =SUM(F11:F20) -> 467100 | G21: =SUM(G11:G20) -> 51900

Sheet Project 2
A1: Practical Data Set
A2: 1. Use UPPER() to create an ALL-CAPS version of the Full Name column
A3: 2. Use LEFT() to extract the first name and RIGHT() to extract the domain from Email
A4: 3. Use LEN() to count the number of characters in each employee's full name
A5: 4. Use TODAY() and DATEDIF() to calculate years of service from Start Date
A6: 5. Use SUM, AVERAGE, MIN, MAX on the Salary column
A7: 6. Use TEXT() to display the Start Date in 'DD MMM YYYY' format
A8: 7. Use CONCAT() to build a greeting: 'Hello, [First Name]!'
A10: EmpID | B10: Full Name | C10: Start Date | D10: Salary | E10: Dept | F10: Email | G10: First Name | H10: Domain Name | I10: Full Name ( Length ) | J10: GREETING | K10: YEARS OF SERVICE
A11: 1001 | B11: =UPPER("Jim Halpert") -> JIM HALPERT | C11: 37197 | D11: 45000 | E11: Sales | F11: Jim.Halpert@DunderMifflin.com | G11: =LEFT(B11,3) -> JIM | H11: =RIGHT(F11,17) -> DunderMifflin.com | I11: =LEN(B11) -> 11 | J11: =_xlfn.CONCAT("HI,"," ",G11) -> HI, JIM | K11: =DATEDIF(C11,TODAY(),"Y") -> 24
A12: 1002 | B12: =UPPER("Pam Beasley") -> PAM BEASLEY | C12: 36436 | D12: 36000 | E12: Admin | F12: Pam.Beasley@DunderMifflin.com | G12: =LEFT(B12,3) -> PAM | H12: =RIGHT(F12,17) -> DunderMifflin.com | I12: =LEN(B12) -> 11 | J12: =_xlfn.CONCAT("HI,"," ",G12) -> HI, PAM | K12: =DATEDIF(C12,TODAY(),"Y") -> 26
A13: 1003 | B13: =UPPER("Dwight Schrute") -> DWIGHT SCHRUTE | C13: 36711 | D13: 63000 | E13: Sales | F13: Dwight.Schrute@AOL.com | G13: =LEFT(B13,6) -> DWIGHT | H13: =RIGHT(F13,7) -> AOL.com | I13: =LEN(B13) -> 14 | J13: =_xlfn.CONCAT("HI,"," ",G13) -> HI, DWIGHT | K13: =DATEDIF(C13,TODAY(),"Y") -> 26
A14: 1004 | B14: =UPPER("Angela Martin") -> ANGELA MARTIN | C14: 36530 | D14: 47000 | E14: Accounting | F14: Angela.Martin@DunderMifflin.com | G14: =LEFT(B14,6) -> ANGELA | H14: =RIGHT(F14,17) -> DunderMifflin.com | I14: =LEN(B14) -> 13 | J14: =_xlfn.CONCAT("HI,"," ",G14) -> HI, ANGELA | K14: =DATEDIF(C14,TODAY(),"Y") -> 26
A15: 1005 | B15: =UPPER("Toby Flenderson") -> TOBY FLENDERSON | C15: 37017 | D15: 50000 | E15: HR | F15: Toby.Flenderson@DunderMifflin.com | G15: =LEFT(B15,4) -> TOBY | H15: =RIGHT(F15,17) -> DunderMifflin.com | I15: =LEN(B15) -> 15 | J15: =_xlfn.CONCAT("HI,"," ",G15) -> HI, TOBY | K15: =DATEDIF(C15,TODAY(),"Y") -> 25
A16: 1006 | B16: =UPPER("Michael Scott") -> MICHAEL SCOTT | C16: 37017 | D16: 65000 | E16: Management | F16: Michael.Scott@DunderMifflin.com | G16: =LEFT(B16,7) -> MICHAEL | H16: =RIGHT(F16,17) -> DunderMifflin.com | I16: =LEN(B16) -> 13 | J16: =_xlfn.CONCAT("HI,"," ",G16) -> HI, MICHAEL | K16: =DATEDIF(C16,TODAY(),"Y") -> 25
A17: 1007 | B17: =UPPER("Meredith Palmer") -> MEREDITH PALMER | C17: 37933 | D17: 55000 | E17: Supply | F17: Meredith.Palmer@Yahoo.com | G17: =LEFT(B17,8) -> MEREDITH | H17: =RIGHT(F17,9) -> Yahoo.com | I17: =LEN(B17) -> 15 | J17: =_xlfn.CONCAT("HI,"," ",G17) -> HI, MEREDITH | K17: =DATEDIF(C17,TODAY(),"Y") -> 22
A18: 1008 | B18: =UPPER("Stanley Hudson") -> STANLEY HUDSON | C18: 37416 | D18: 48000 | E18: Sales | F18: Stanley.Hudson@gmail.com | G18: =LEFT(B18,7) -> STANLEY | H18: =RIGHT(F18,9) -> gmail.com | I18: =LEN(B18) -> 14 | J18: =_xlfn.CONCAT("HI,"," ",G18) -> HI, STANLEY | K18: =DATEDIF(C18,TODAY(),"Y") -> 24
A21: =CONCATENATE("TOTAL SALARY : ",SUM($D$11:$D$18)) -> TOTAL SALARY : 409000
A22: =CONCATENATE("AVERAGE SALARY : ",AVERAGE($D$11:$D$18)) -> AVERAGE SALARY : 51125
A23: =CONCATENATE("MINIMIUM SALARY : ",MIN($D$11:$D$18)) -> MINIMIUM SALARY : 36000
A24: =CONCATENATE("MAXIMIUM SALARY : ",MAX($D$11:$D$18)) -> MAXIMIUM SALARY : 65000

Sheet Project 3 
A3: TASKS
A4: 1. Use SUMIF to find total salary for each department (Sales, Accounting, HR)
A5: 2. Use COUNTIF to count how many employees are in each department
A6: 3. Use SUMIF to total salaries for Male employees and separately for Female employees
A7: 4. Use SUMIFS to find total salary for Male employees in Sales
A8: 5. Use COUNTIFS to count Female employees earning more than $45,000
A9: 6. Use AVERAGEIF to find the average salary for Accounting department
A10: 7. Use COUNTIF with a wildcard (*) to count all emails ending in '@DunderMifflin.com'
A13: EmpID | B13: Full Name | C13: Gender | D13: Department | E13: Salary | F13: Total employees in each dept | G13: Counts
A14: 1001 | B14: Jim Halpert | C14: M | D14: Sales | E14: 45000 | F14: Accounting | G14: =COUNTIF(D14:D25,D17) -> 3
A15: 1002 | B15: Pam Beasley | C15: F | D15: Admin | E15: 36000 | F15: Sales | G15: =COUNTIF(D14:D25,D14) -> 4
A16: 1003 | B16: Dwight Schrute | C16: M | D16: Sales | E16: 63000 | F16: Admin | G16: =COUNTIF(D14:D25,D15) -> 1
A17: 1004 | B17: Angela Martin | C17: F | D17: Accounting | E17: 47000 | F17: Management | G17: =COUNTIF(D14:D25,D19) -> 1
A18: 1005 | B18: Toby Flenderson | C18: M | D18: HR | E18: 50000 | F18: Supply | G18: =COUNTIF(D14:D25,D20) -> 1
A19: 1006 | B19: Michael Scott | C19: M | D19: Management | E19: 65000 | F19: HR | G19: =COUNTIF(D14:D25,D18) -> 1
A20: 1007 | B20: Meredith Palmer | C20: F | D20: Supply | E20: 55000 | F20: Temp | G20: =COUNTIF(D14:D25,D25) -> 1
A21: 1008 | B21: Stanley Hudson | C21: M | D21: Sales | E21: 48000
A22: 1009 | B22: Kevin Malone | C22: M | D22: Accounting | E22: 52000
A23: 1010 | B23: Oscar Martinez | C23: M | D23: Accounting | E23: 58000
A24: 1011 | B24: Phyllis Vance | C24: F | D24: Sales | E24: 44000
A25: 1012 | B25: Ryan Howard | C25: M | D25: Temp | E25: 32000
A27: =CONCATENATE("ACCOUNTING TOTAL SALARY : ",SUMIF($D$14:$D$25,D17,E14:E25)) -> ACCOUNTING TOTAL SALARY : 157000 | B27: =CONCATENATE("FEMALE EMPLYEE > 45000 : ",COUNTIFS($C$14:$C$25,C15,$E$14:$E$25,">45000")) -> FEMALE EMPLYEE > 45000 : 2
A28: =CONCATENATE("SALES TOTAL SALARY : ",SUMIF($D$14:$D$25,D16,E14:$E$25)) -> SALES TOTAL SALARY : 200000
A29: =CONCATENATE("HR TOTAL SALARY : ",SUMIF($D$14:$D$25,D18,E15:$E$25)) -> HR TOTAL SALARY : 65000
A30: =CONCATENATE("MALE TOTAL SALARY : ",SUMIF($C$14:$C$25,C14,$E$14:$E$25)) -> MALE TOTAL SALARY : 413000
A31: =CONCATENATE("FEMALE TOTAL SALARY : ",SUMIF($C$14:$C$25,C15,$E$14:$E$25)) -> FEMALE TOTAL SALARY : 182000
A32: =CONCATENATE("ACCOUNTING AVERAGE SALARY : ",AVERAGEIF($D$14:$D$25,$D$17,$E$14:$E$25)) -> ACCOUNTING AVERAGE SALARY : 52333.3333333333

Sheet Project 4
A1: TASKS
A2: 1. Use RANDBETWEEN to generate 10 random test scores between 0 and 100
A3: 2. Use MROUND to round each score to the nearest 5
A4: 3. Use ROUND to round each raw score to the nearest 10
A5: 4. Create an Autofill series for dates: Jan 1 2024 to Dec 31 2024 (monthly)
A6: 5. Use RAND() * 100 to generate decimal scores, then compare to RANDBETWEEN
A7: 6. Use MOD to identify which employees have even-numbered IDs
A8: 7. Use ROUNDUP and ROUNDDOWN on the raw scores — compare the differences
A14: EmpID | B14: Name | C14: Raw Score | D14: Rounded Score | E14: Grade Tier | F14: formulas (RANDBETWEEN) | G14: TEST SCORES | H14: NEAREST MULTIPLE | I14: DATES | J14: TEST SCORES2 | K14: COMPARISON | L14: EMLOYEE IDS | M14: score difference
A15: 1001 | B15: Jim | C15: =RANDBETWEEN(50,100) -> 60 | D15: =MROUND(C15,5) -> 60 | E15: =RANDBETWEEN(1,5) -> 2 | F15: =RANDBETWEEN(30000,80000) -> 55736 | G15: =RANDBETWEEN(0,100) -> 36 | H15: =MROUND(G15,5) -> 35 | I15: 45292 | J15: =RAND()*100 -> 17.787796 | K15: =IF(G15>J15,"A is greater "," B is greater ") -> A is greater | L15: =IF(MOD(A15,2)=0,"Employee is even","Employee is odd") -> Employee is odd | M15: =ROUNDUP(C15,0)-ROUNDDOWN(C15,0) -> 0
A16: 1002 | B16: Pam | C16: =RANDBETWEEN(50,100) -> 75 | D16: =MROUND(C16,5) -> 75 | E16: =RANDBETWEEN(1,5) -> 5 | F16: =RANDBETWEEN(30000,80000) -> 55907 | G16: =RANDBETWEEN(0,100) -> 22 | H16: =MROUND(G16,5) -> 20 | I16: 45323 | J16: =RAND()*100 -> 68.051957 | K16: =IF(G16>J16,"A is greater "," B is greater ") -> B is greater | L16: =IF(MOD(A16,2)=0,"Employee is even","Employee is odd") -> Employee is even | M16: =ROUNDUP(C16,0)-ROUNDDOWN(C16,0) -> 0
A17: 1003 | B17: Dwight | C17: =RANDBETWEEN(50,100) -> 76 | D17: =MROUND(C17,5) -> 75 | E17: =RANDBETWEEN(1,5) -> 1 | F17: =RANDBETWEEN(30000,80000) -> 60546 | G17: =RANDBETWEEN(0,100) -> 4 | H17: =MROUND(G17,5) -> 5 | I17: 45352 | J17: =RAND()*100 -> 44.16729 | K17: =IF(G17>J17,"A is greater "," B is greater ") -> B is greater | L17: =IF(MOD(A17,2)=0,"Employee is even","Employee is odd") -> Employee is odd | M17: =ROUNDUP(C17,0)-ROUNDDOWN(C17,0) -> 0
A18: 1004 | B18: Angela | C18: =RANDBETWEEN(50,100) -> 60 | D18: =MROUND(C18,5) -> 60 | E18: =RANDBETWEEN(1,5) -> 5 | F18: =RANDBETWEEN(30000,80000) -> 59121 | G18: =RANDBETWEEN(0,100) -> 55 | H18: =MROUND(G18,5) -> 55 | I18: 45383 | J18: =RAND()*100 -> 55.082972 | K18: =IF(G18>J18,"A is greater "," B is greater ") -> B is greater | L18: =IF(MOD(A18,2)=0,"Employee is even","Employee is odd") -> Employee is even | M18: =ROUNDUP(C18,0)-ROUNDDOWN(C18,0) -> 0
A19: 1005 | B19: Toby | C19: =RANDBETWEEN(50,100) -> 85 | D19: =MROUND(C19,5) -> 85 | E19: =RANDBETWEEN(1,5) -> 3 | F19: =RANDBETWEEN(30000,80000) -> 73333 | G19: =RANDBETWEEN(0,100) -> 97 | H19: =MROUND(G19,5) -> 95 | I19: 45413 | J19: =RAND()*100 -> 36.421217 | K19: =IF(G19>J19,"A is greater "," B is greater ") -> A is greater | L19: =IF(MOD(A19,2)=0,"Employee is even","Employee is odd") -> Employee is odd | M19: =ROUNDUP(C19,0)-ROUNDDOWN(C19,0) -> 0
A20: 1006 | B20: Michael | C20: =RANDBETWEEN(50,100) -> 73 | D20: =MROUND(C20,5) -> 75 | E20: =RANDBETWEEN(1,5) -> 2 | F20: =RANDBETWEEN(30000,80000) -> 64732 | G20: =RANDBETWEEN(0,100) -> 46 | H20: =MROUND(G20,5) -> 45 | I20: 45444 | J20: =RAND()*100 -> 47.482958 | K20: =IF(G20>J20,"A is greater "," B is greater ") -> B is greater | L20: =IF(MOD(A20,2)=0,"Employee is even","Employee is odd") -> Employee is even | M20: =ROUNDUP(C20,0)-ROUNDDOWN(C20,0) -> 0
A21: 1007 | B21: Meredith | C21: =RANDBETWEEN(50,100) -> 88 | D21: =MROUND(C21,5) -> 90 | E21: =RANDBETWEEN(1,5) -> 2 | F21: =RANDBETWEEN(30000,80000) -> 34732 | G21: =RANDBETWEEN(0,100) -> 66 | H21: =MROUND(G21,5) -> 65 | I21: 45474 | J21: =RAND()*100 -> 71.73751 | K21: =IF(G21>J21,"A is greater "," B is greater ") -> B is greater | L21: =IF(MOD(A21,2)=0,"Employee is even","Employee is odd") -> Employee is odd | M21: =ROUNDUP(C21,0)-ROUNDDOWN(C21,0) -> 0
A22: 1008 | B22: Stanley | C22: =RANDBETWEEN(50,100) -> 66 | D22: =MROUND(C22,5) -> 65 | E22: =RANDBETWEEN(1,5) -> 3 | F22: =RANDBETWEEN(30000,80000) -> 74588 | G22: =RANDBETWEEN(0,100) -> 53 | H22: =MROUND(G22,5) -> 55 | I22: 45505 | J22: =RAND()*100 -> 38.774804 | K22: =IF(G22>J22,"A is greater "," B is greater ") -> A is greater | L22: =IF(MOD(A22,2)=0,"Employee is even","Employee is odd") -> Employee is even | M22: =ROUNDUP(C22,0)-ROUNDDOWN(C22,0) -> 0
A23: 1009 | B23: Kevin | C23: =RANDBETWEEN(50,100) -> 70 | D23: =MROUND(C23,5) -> 70 | E23: =RANDBETWEEN(1,5) -> 3 | F23: =RANDBETWEEN(30000,80000) -> 62365 | G23: =RANDBETWEEN(0,100) -> 52 | H23: =MROUND(G23,5) -> 50 | I23: 45536 | J23: =RAND()*100 -> 78.006961 | K23: =IF(G23>J23,"A is greater "," B is greater ") -> B is greater | L23: =IF(MOD(A23,2)=0,"Employee is even","Employee is odd") -> Employee is odd | M23: =ROUNDUP(C23,0)-ROUNDDOWN(C23,0) -> 0
A24: 1010 | B24: Oscar | C24: =RANDBETWEEN(50,100) -> 82 | D24: =MROUND(C24,5) -> 80 | E24: =RANDBETWEEN(1,5) -> 3 | F24: =RANDBETWEEN(30000,80000) -> 43025 | G24: =RANDBETWEEN(0,100) -> 75 | H24: =MROUND(G24,5) -> 75 | I24: 45566 | J24: =RAND()*100 -> 20.206501 | K24: =IF(G24>J24,"A is greater "," B is greater ") -> A is greater | L24: =IF(MOD(A24,2)=0,"Employee is even","Employee is odd") -> Employee is even | M24: =ROUNDUP(C24,0)-ROUNDDOWN(C24,0) -> 0

Sheet Project 5 
A1: TASKS | H1: Multiplication Table | I1: 1 | J1: 2 | K1: 3 | L1: 4 | M1: 5 | N1: 6 | O1: 7 | P1: 8 | Q1: 9
A2: 1. Use Data > Text to Columns to split Full Name into First Name and Last Name | H2: 1 | I2: =$H2*I$1 -> 1 | J2: =$H2*J$1 -> 2 | K2: =$H2*K$1 -> 3 | L2: =$H2*L$1 -> 4 | M2: =$H2*M$1 -> 5 | N2: =$H2*N$1 -> 6 | O2: =$H2*O$1 -> 7 | P2: =$H2*P$1 -> 8 | Q2: =$H2*Q$1 -> 9
A3: 2. Build a price table using an absolute reference for a VAT rate stored in one cell | H3: 2 | I3: =$H3*I$1 -> 2 | J3: =$H3*J$1 -> 4 | K3: =$H3*K$1 -> 6 | L3: =$H3*L$1 -> 8 | M3: =$H3*M$1 -> 10 | N3: =$H3*N$1 -> 12 | O3: =$H3*O$1 -> 14 | P3: =$H3*P$1 -> 16 | Q3: =$H3*Q$1 -> 18
A4: 3. Create a multiplication table (1–10 × 1–10) using mixed references ($A1 and A$1) | H4: 3 | I4: =$H4*I$1 -> 3 | J4: =$H4*J$1 -> 6 | K4: =$H4*K$1 -> 9 | L4: =$H4*L$1 -> 12 | M4: =$H4*M$1 -> 15 | N4: =$H4*N$1 -> 18 | O4: =$H4*O$1 -> 21 | P4: =$H4*P$1 -> 24 | Q4: =$H4*Q$1 -> 27
A5: 4. Calculate Net Salary for all employees using an absolute reference for the tax rate | H5: 4 | I5: =$H5*I$1 -> 4 | J5: =$H5*J$1 -> 8 | K5: =$H5*K$1 -> 12 | L5: =$H5*L$1 -> 16 | M5: =$H5*M$1 -> 20 | N5: =$H5*N$1 -> 24 | O5: =$H5*O$1 -> 28 | P5: =$H5*P$1 -> 32 | Q5: =$H5*Q$1 -> 36
A6: 5. Change the tax rate cell to 25% — verify all Net Salary values update automatically | H6: 5 | I6: =$H6*I$1 -> 5 | J6: =$H6*J$1 -> 10 | K6: =$H6*K$1 -> 15 | L6: =$H6*L$1 -> 20 | M6: =$H6*M$1 -> 25 | N6: =$H6*N$1 -> 30 | O6: =$H6*O$1 -> 35 | P6: =$H6*P$1 -> 40 | Q6: =$H6*Q$1 -> 45
A7: 6. Use a cross-sheet reference to pull salary data from another sheet | H7: 6 | I7: =$H7*I$1 -> 6 | J7: =$H7*J$1 -> 12 | K7: =$H7*K$1 -> 18 | L7: =$H7*L$1 -> 24 | M7: =$H7*M$1 -> 30 | N7: =$H7*N$1 -> 36 | O7: =$H7*O$1 -> 42 | P7: =$H7*P$1 -> 48 | Q7: =$H7*Q$1 -> 54
A8: 7. Press F4 after clicking a cell reference in the formula bar to cycle through reference types | H8: 7 | I8: =$H8*I$1 -> 7 | J8: =$H8*J$1 -> 14 | K8: =$H8*K$1 -> 21 | L8: =$H8*L$1 -> 28 | M8: =$H8*M$1 -> 35 | N8: =$H8*N$1 -> 42 | O8: =$H8*O$1 -> 49 | P8: =$H8*P$1 -> 56 | Q8: =$H8*Q$1 -> 63
H9: 8 | I9: =$H9*I$1 -> 8 | J9: =$H9*J$1 -> 16 | K9: =$H9*K$1 -> 24 | L9: =$H9*L$1 -> 32 | M9: =$H9*M$1 -> 40 | N9: =$H9*N$1 -> 48 | O9: =$H9*O$1 -> 56 | P9: =$H9*P$1 -> 64 | Q9: =$H9*Q$1 -> 72
H10: 9 | I10: =$H10*I$1 -> 9 | J10: =$H10*J$1 -> 18 | K10: =$H10*K$1 -> 27 | L10: =$H10*L$1 -> 36 | M10: =$H10*M$1 -> 45 | N10: =$H10*N$1 -> 54 | O10: =$H10*O$1 -> 63 | P10: =$H10*P$1 -> 72 | Q10: =$H10*Q$1 -> 81
H11: 10 | I11: =$H11*I$1 -> 10 | J11: =$H11*J$1 -> 20 | K11: =$H11*K$1 -> 30 | L11: =$H11*L$1 -> 40 | M11: =$H11*M$1 -> 50 | N11: =$H11*N$1 -> 60 | O11: =$H11*O$1 -> 70 | P11: =$H11*P$1 -> 80 | Q11: =$H11*Q$1 -> 90
A15: Full Name (to split) | B15: First Name | C15: Last Name | D15: Email | E15: Salary | F15: Tax Rate : 0.25 | G15: Price Table | H15: Net Salary | I15: Salary (cross sheet ) | R15: 10
A16: Jim Halpert | B16: Jim | C16: Halpert | E16: 45000 | F16: =E16*(1-$G$33) -> 45000 | G16: =E16*$G$33 -> 0 | H16: =E16-(E16*0.2) -> 36000 | I16: ='Project 2'!D11 -> 45000 | R16: =$H2*R$15 -> 10
A17: Pam Beasley | B17: Pam | C17: Beasley | E17: 36000 | F17: =E17*(1-$G$33) -> 36000 | G17: =E17*$G$33 -> 0 | H17: =E17-(E17*0.2) -> 28800 | I17: ='Project 2'!D12 -> 36000 | R17: =$H3*R$15 -> 20
A18: Dwight Schrute | B18: Dwight | C18: Schrute | E18: 63000 | F18: =E18*(1-$G$33) -> 63000 | G18: =E18*$G$33 -> 0 | H18: =E18-(E18*0.2) -> 50400 | I18: ='Project 2'!D13 -> 63000 | R18: =$H4*R$15 -> 30
A19: Angela Martin | B19: Angela | C19: Martin | E19: 47000 | F19: =E19*(1-$G$33) -> 47000 | G19: =E19*$G$33 -> 0 | H19: =E19-(E19*0.2) -> 37600 | I19: ='Project 2'!D14 -> 47000 | R19: =$H5*R$15 -> 40
A20: Toby Flenderson | B20: Toby | C20: Flenderson | E20: 50000 | F20: =E20*(1-$G$33) -> 50000 | G20: =E20*$G$33 -> 0 | H20: =E20-(E20*0.2) -> 40000 | I20: ='Project 2'!D15 -> 50000 | R20: =$H6*R$15 -> 50
A21: Michael Scott | B21: Michael | C21: Scott | E21: 65000 | F21: =E21*(1-$G$33) -> 65000 | G21: =E21*$G$33 -> 0 | H21: =E21-(E21*0.2) -> 52000 | I21: ='Project 2'!D16 -> 65000 | R21: =$H7*R$15 -> 60
A22: Meredith Palmer | B22: Meredith | C22: Palmer | E22: 55000 | F22: =E22*(1-$G$33) -> 55000 | G22: =E22*$G$33 -> 0 | H22: =E22-(E22*0.2) -> 44000 | I22: ='Project 2'!D17 -> 55000 | R22: =$H8*R$15 -> 70
A23: Stanley Hudson | B23: Stanley | C23: Hudson | E23: 48000 | F23: =E23*(1-$G$33) -> 48000 | G23: =E23*$G$33 -> 0 | H23: =E23-(E23*0.2) -> 38400 | I23: ='Project 2'!D18 -> 48000 | R23: =$H9*R$15 -> 80
R24: =$H10*R$15 -> 90
R25: =$H11*R$15 -> 100

Sheet Project 6 
A3: 1. Convert the dataset to an Excel Table (Ctrl+T) — name it 'EmployeeTable'
A4: EmpID | B4: Full Name | C4: Gender | D4: Department | E4: Salary | F4: Job Title | G4: Start Date | H4: Tenure (Yrs) | I4: Email
A5: 1006 | B5: Michael Scott | C5: M | D5: Management | E5: 65000 | F5: Regional Manager | G5: 2001-05-06 | H5: =DATEDIF(DATE(2001,5,6),TODAY(),"Y") -> 25 | I5: michael.scott@dundermifflin.com
A6: 1003 | B6: Dwight Schrute | C6: M | D6: Sales | E6: 63000 | F6: Assistant RM | G6: 2000-07-04 | H6: =DATEDIF(DATE(2000,7,4),TODAY(),"Y") -> 26 | I6: dwight.schrute@aol.com
A7: 1010 | B7: Oscar Martinez | C7: M | D7: Accounting | E7: 58000 | F7: Senior Accountant | G7: 2002-03-15 | H7: =DATEDIF(DATE(2002,3,15),TODAY(),"Y") -> 24 | I7: oscar.martinez@dundermifflin.com
A8: 1007 | B8: Meredith Palmer | C8: F | D8: Supply | E8: 55000 | F8: Supplier Relations | G8: 2003-11-08 | H8: =DATEDIF(DATE(2003,11,8),TODAY(),"Y") -> 22 | I8: meredith.palmer@yahoo.com
A9: 1009 | B9: Kevin Malone | C9: M | D9: Accounting | E9: 52000 | F9: Accountant | G9: 2003-08-10 | H9: =DATEDIF(DATE(2003,8,10),TODAY(),"Y") -> 23 | I9: kevin.malone@dundermifflin.com
A10: 1005 | B10: Toby Flenderson | C10: M | D10: HR | E10: 50000 | F10: HR Rep | G10: 2001-05-06 | H10: =DATEDIF(DATE(2001,5,6),TODAY(),"Y") -> 25 | I10: toby.flenderson@dundermifflin.com
A11: 1008 | B11: Stanley Hudson | C11: M | D11: Sales | E11: 48000 | F11: Salesman | G11: 2002-06-09 | H11: =DATEDIF(DATE(2002,6,9),TODAY(),"Y") -> 24 | I11: stanley.hudson@gmail.com
A12: 1004 | B12: Angela Martin | C12: F | D12: Accounting | E12: 47000 | F12: Accountant | G12: 2000-01-05 | H12: =DATEDIF(DATE(2000,1,5),TODAY(),"Y") -> 26 | I12: angela.martin@dundermifflin.com
A13: 1001 | B13: Jim Halpert | C13: M | D13: Sales | E13: 45000 | F13: Salesman | G13: 2001-11-02 | H13: =DATEDIF(DATE(2001,11,2),TODAY(),"Y") -> 24 | I13: jim.halpert@dundermifflin.com
A14: 1011 | B14: Phyllis Vance | C14: F | D14: Sales | E14: 44000 | F14: Saleswoman | G14: 2001-07-11 | H14: =DATEDIF(DATE(2001,7,11),TODAY(),"Y") -> 25 | I14: phyllis.vance@dundermifflin.com
A15: 1002 | B15: Pam Beasley | C15: F | D15: Admin | E15: 36000 | F15: Receptionist | G15: 1999-10-03 | H15: =DATEDIF(DATE(1999,10,3),TODAY(),"Y") -> 26 | I15: pam.beasley@dundermifflin.com
A16: 1012 | B16: Ryan Howard | C16: M | D16: Temp | E16: 32000 | F16: Temp | G16: 2004-01-20 | H16: =DATEDIF(DATE(2004,1,20),TODAY(),"Y") -> 22 | I16: ryan.howard@dundermifflin.com
A21: 2. Sort the table by Salary from highest to lowest
A22: EmpID | B22: Full Name | C22: Gender | D22: Department | E22: Salary | F22: Job Title | G22: Start Date | H22: Tenure (Yrs) | I22: Email
A23: 1006 | B23: Michael Scott | C23: M | D23: Management | E23: 65000 | F23: Regional Manager | G23: 2001-05-06 | H23: =DATEDIF(DATE(2001,5,6),TODAY(),"Y") -> 25 | I23: michael.scott@dundermifflin.com
A24: 1003 | B24: Dwight Schrute | C24: M | D24: Sales | E24: 63000 | F24: Assistant RM | G24: 2000-07-04 | H24: =DATEDIF(DATE(2000,7,4),TODAY(),"Y") -> 26 | I24: dwight.schrute@aol.com
A25: 1010 | B25: Oscar Martinez | C25: M | D25: Accounting | E25: 58000 | F25: Senior Accountant | G25: 2002-03-15 | H25: =DATEDIF(DATE(2002,3,15),TODAY(),"Y") -> 24 | I25: oscar.martinez@dundermifflin.com
A26: 1007 | B26: Meredith Palmer | C26: F | D26: Supply | E26: 55000 | F26: Supplier Relations | G26: 2003-11-08 | H26: =DATEDIF(DATE(2003,11,8),TODAY(),"Y") -> 22 | I26: meredith.palmer@yahoo.com
A27: 1009 | B27: Kevin Malone | C27: M | D27: Accounting | E27: 52000 | F27: Accountant | G27: 2003-08-10 | H27: =DATEDIF(DATE(2003,8,10),TODAY(),"Y") -> 23 | I27: kevin.malone@dundermifflin.com
A28: 1005 | B28: Toby Flenderson | C28: M | D28: HR | E28: 50000 | F28: HR Rep | G28: 2001-05-06 | H28: =DATEDIF(DATE(2001,5,6),TODAY(),"Y") -> 25 | I28: toby.flenderson@dundermifflin.com
A29: 1008 | B29: Stanley Hudson | C29: M | D29: Sales | E29: 48000 | F29: Salesman | G29: 2002-06-09 | H29: =DATEDIF(DATE(2002,6,9),TODAY(),"Y") -> 24 | I29: stanley.hudson@gmail.com
A30: 1004 | B30: Angela Martin | C30: F | D30: Accounting | E30: 47000 | F30: Accountant | G30: 2000-01-05 | H30: =DATEDIF(DATE(2000,1,5),TODAY(),"Y") -> 26 | I30: angela.martin@dundermifflin.com
A31: 1001 | B31: Jim Halpert | C31: M | D31: Sales | E31: 45000 | F31: Salesman | G31: 2001-11-02 | H31: =DATEDIF(DATE(2001,11,2),TODAY(),"Y") -> 24 | I31: jim.halpert@dundermifflin.com
A32: 1011 | B32: Phyllis Vance | C32: F | D32: Sales | E32: 44000 | F32: Saleswoman | G32: 2001-07-11 | H32: =DATEDIF(DATE(2001,7,11),TODAY(),"Y") -> 25 | I32: phyllis.vance@dundermifflin.com
A33: 1002 | B33: Pam Beasley | C33: F | D33: Admin | E33: 36000 | F33: Receptionist | G33: 1999-10-03 | H33: =DATEDIF(DATE(1999,10,3),TODAY(),"Y") -> 26 | I33: pam.beasley@dundermifflin.com
A34: 1012 | B34: Ryan Howard | C34: M | D34: Temp | E34: 32000 | F34: Temp | G34: 2004-01-20 | H34: =DATEDIF(DATE(2004,1,20),TODAY(),"Y") -> 22 | I34: ryan.howard@dundermifflin.com
A39: 3. Apply a Custom Sort: first by Department (A→Z), then by Salary (↓)
A40: EmpID | B40: Full Name | C40: Gender | D40: Department | E40: Salary | F40: Job Title | G40: Start Date | H40: Tenure (Yrs) | I40: Email
A41: 1010 | B41: Oscar Martinez | C41: M | D41: Accounting | E41: 58000 | F41: Senior Accountant | G41: 2002-03-15 | H41: =DATEDIF(DATE(2002,3,15),TODAY(),"Y") -> 24 | I41: oscar.martinez@dundermifflin.com
A42: 1009 | B42: Kevin Malone | C42: M | D42: Accounting | E42: 52000 | F42: Accountant | G42: 2003-08-10 | H42: =DATEDIF(DATE(2003,8,10),TODAY(),"Y") -> 23 | I42: kevin.malone@dundermifflin.com
A43: 1004 | B43: Angela Martin | C43: F | D43: Accounting | E43: 47000 | F43: Accountant | G43: 2000-01-05 | H43: =DATEDIF(DATE(2000,1,5),TODAY(),"Y") -> 26 | I43: angela.martin@dundermifflin.com
A44: 1002 | B44: Pam Beasley | C44: F | D44: Admin | E44: 36000 | F44: Receptionist | G44: 1999-10-03 | H44: =DATEDIF(DATE(1999,10,3),TODAY(),"Y") -> 26 | I44: pam.beasley@dundermifflin.com
A45: 1005 | B45: Toby Flenderson | C45: M | D45: HR | E45: 50000 | F45: HR Rep | G45: 2001-05-06 | H45: =DATEDIF(DATE(2001,5,6),TODAY(),"Y") -> 25 | I45: toby.flenderson@dundermifflin.com
A46: 1006 | B46: Michael Scott | C46: M | D46: Management | E46: 65000 | F46: Regional Manager | G46: 2001-05-06 | H46: =DATEDIF(DATE(2001,5,6),TODAY(),"Y") -> 25 | I46: michael.scott@dundermifflin.com
A47: 1003 | B47: Dwight Schrute | C47: M | D47: Sales | E47: 63000 | F47: Assistant RM | G47: 2000-07-04 | H47: =DATEDIF(DATE(2000,7,4),TODAY(),"Y") -> 26 | I47: dwight.schrute@aol.com
A48: 1008 | B48: Stanley Hudson | C48: M | D48: Sales | E48: 48000 | F48: Salesman | G48: 2002-06-09 | H48: =DATEDIF(DATE(2002,6,9),TODAY(),"Y") -> 24 | I48: stanley.hudson@gmail.com
A49: 1001 | B49: Jim Halpert | C49: M | D49: Sales | E49: 45000 | F49: Salesman | G49: 2001-11-02 | H49: =DATEDIF(DATE(2001,11,2),TODAY(),"Y") -> 24 | I49: jim.halpert@dundermifflin.com
A50: 1011 | B50: Phyllis Vance | C50: F | D50: Sales | E50: 44000 | F50: Saleswoman | G50: 2001-07-11 | H50: =DATEDIF(DATE(2001,7,11),TODAY(),"Y") -> 25 | I50: phyllis.vance@dundermifflin.com
...

Sheet Project 7
A1: TASKS
A2: 1. Apply Freeze Panes to lock row 24 (header) and column B (Student_ID)
A3: 2. Use Highlight Cell Rules: colour Mental_Health_Score > 7.5 in Green, < 5.5 in Red
A4: 3. Apply Data Bars to the Avg_Daily_Usage_Hours column
A5: 4. Apply a Colour Scale (Green-Yellow-Red) to the Sleep_Hours_Per_Night column
A6: 5. Use Icon Sets (3 arrows) on the Mental_Health_Score column
A7: 6. Create a custom rule: highlight entire row Red if Overall_Impact = 'Negative'
A8: 7. Use Top/Bottom Rules to highlight the top 5 Mental_Health_Scores in Gold
A11: Student_ID | B11: Age | C11: Gender | D11: Academic_Level | E11: Country | F11: Avg_Daily_Usage_Hours | G11: Most_Used_Platform | H11: Affects_Academic | I11: Sleep_Hours | J11: Mental_Health_Score | K11: Overall_Impact
A12: 232 | B12: 21 | C12: Male | D12: Undergraduate | E12: Other | F12: 4 | G12: Facebook | H12: No | I12: 6.7 | J12: 6.8 | K12: Neutral
A13: 564 | B13: 23 | C13: Female | D13: Undergraduate | E13: Other | F13: 1.6 | G13: LinkedIn | H13: No | I13: 8.6 | J13: 7.6 | K13: Positive
A14: 788 | B14: 22 | C14: Male | D14: Graduate | E14: Canada | F14: 4.6 | G14: Instagram | H14: No | I14: 6.7 | J14: 7 | K14: Neutral
A15: 686 | B15: 18 | C15: Male | D15: Undergraduate | E15: Other | F15: 7 | G15: Snapchat | H15: Yes | I15: 5.4 | J15: 5.3 | K15: Negative
A16: 608 | B16: 24 | C16: Female | D16: High School | E16: Other | F16: 7.5 | G16: Facebook | H16: Yes | I16: 5 | J16: 4.4 | K16: Negative
A17: 370 | B17: 19 | C17: Female | D17: High School | E17: Other | F17: 4.1 | G17: Twitter | H17: Yes | I17: 6.8 | J17: 6.8 | K17: Neutral
A18: 862 | B18: 22 | C18: Female | D18: Graduate | E18: Other | F18: 8 | G18: Instagram | H18: Yes | I18: 5.2 | J18: 5.3 | K18: Negative
A19: 520 | B19: 21 | C19: Female | D19: Graduate | E19: Other | F19: 6 | G19: Facebook | H19: Yes | I19: 5.7 | J19: 4.7 | K19: Negative
A20: 703 | B20: 24 | C20: Male | D20: Undergraduate | E20: USA | F20: 4.7 | G20: YouTube | H20: No | I20: 7 | J20: 6.2 | K20: Neutral
A21: 33 | B21: 19 | C21: Male | D21: High School | E21: Other | F21: 3.6 | G21: TikTok | H21: No | I21: 8.1 | J21: 8.6 | K21: Positive
A22: 519 | B22: 18 | C22: Male | D22: Graduate | E22: Other | F22: 4.1 | G22: LinkedIn | H22: No | I22: 7.3 | J22: 6.8 | K22: Neutral
A23: 738 | B23: 18 | C23: Male | D23: High School | E23: Other | F23: 7.6 | G23: Snapchat | H23: Yes | I23: 5.3 | J23: 5.5 | K23: Negative
... A31: 631 | B31: 20 | C31: Male | D31: Undergraduate | E31: Other | F31: 5.5 | G31: Instagram | H31: No | I31: 6.8 | J31: 6.8 | K31: Neutral

Sheet Project 8
A1: TASKS
A2: 1. Use TRIM() to remove leading/trailing spaces from Full Name column
A3: 2. Use PROPER() to fix the case of all names and UPPER() for department codes
A4: 3. Use SUBSTITUTE() to remove commas from salary text ('63,000' → '63000'), then VALUE() to convert
A5: 4. Use LOWER() to standardise all email addresses
A6: 5. Set up Data Validation on Department column: dropdown list of Sales, HR, Accounting, Management, Supply
A7: 6. Set up Data Validation on Age column: whole numbers between 18 and 70
A8: 7. Use Data > Circle Invalid Data to identify any entries that violate your validation rules
A13: EmpID | B13: Full Name | C13: Department | D13: Salary (Text) | E13: Email | F13: Age (Text) | G13: SALARY (Edited)
A14: 1001 | B14: =PROPER(TRIM(" jim halpert ")) -> Jim Halpert | C14: Sales | D14: 45000 | E14: =LOWER("jim.halpert@dundermifflin.com") -> jim.halpert@dundermifflin.com | F14: 21 | G14: =VALUE(SUBSTITUTE(D14,45000,45000)) -> 45000
A15: 1002 | B15: =PROPER(TRIM("PAM BEASLEY")) -> Pam Beasley | C15: =PROPER("admin") -> Admin | D15: 36000 | E15: =LOWER("PAM.BEASLEY@DUNDERMIFFLIN.COM") -> pam.beasley@dundermifflin.com | F15: 30 | G15: =VALUE(SUBSTITUTE(D15,45000,45000)) -> 36000
A16: 1003 | B16: =PROPER(TRIM("Dwight-Schrute")) -> Dwight-Schrute | C16: =PROPER("Sales") -> Sales | D16: 63000 | E16: =LOWER("dwight.schrute@aol.com") -> dwight.schrute@aol.com | F16: 29 | G16: =VALUE(SUBSTITUTE(D16,45000,45000)) -> 63000
A17: 1004 | B17: =PROPER(TRIM("angela martin")) -> Angela Martin | C17: =PROPER("accounting") -> Accounting | D17: 47000 | E17: =LOWER("angela.martin@dundermifflin.com") -> angela.martin@dundermifflin.com | F17: 31 | G17: =VALUE(SUBSTITUTE(D17,45000,45000)) -> 47000
A18: 1005 | B18: =PROPER(TRIM("TOBY FLENDERSON")) -> Toby Flenderson | C18: =PROPER("HR") -> Hr | D18: 50000 | E18: =LOWER("toby.flenderson@dundermifflin.com") -> toby.flenderson@dundermifflin.com | F18: 35 | G18: =VALUE(SUBSTITUTE(D18,45000,45000)) -> 50000
A19: 1006 | B19: =PROPER(TRIM("michael scott")) -> Michael Scott | C19: =PROPER("management") -> Management | D19: 65,000 | E19: =LOWER("Michael.Scott@DunderMifflin.com") -> michael.scott@dundermifflin.com | F19: 55 | G19: =VALUE(SUBSTITUTE(D19,45000,45000)) -> 65000
A20: 1007 | B20: =PROPER(TRIM(" Meredith Palmer")) -> Meredith Palmer | C20: =PROPER("Supply") -> Supply | D20: 55000 | E20: =LOWER("meredith.palmer@yahoo.com") -> meredith.palmer@yahoo.com | F20: 32 | G20: =VALUE(SUBSTITUTE(D20,45000,45000)) -> 55000
A21: 1008 | B21: =PROPER(TRIM("stanley hudson")) -> Stanley Hudson | C21: =PROPER("SALES") -> Sales | D21: 48000 | E21: =LOWER("stanley.hudson@gmail.com") -> stanley.hudson@gmail.com | F21: 38 | G21: =VALUE(SUBSTITUTE(D21,45000,45000)) -> 48000

Sheet Project 9
A1: TASKS
A2: 1. Use TRIM() on Student_ID and Avg_Daily_Usage_Hours to remove stray spaces
A3: 2. Use PROPER() to standardise Gender, Academic_Level, and Country columns
A4: 3. Use LOWER() to standardise the Most_Used_Platform column
A5: 4. Use VALUE() to convert the Student_ID and Avg_Daily_Usage_Hours to numbers
A6: 5. Use COUNTIF to identify and flag the duplicate Student_ID row
A7: 6. Use Data > Remove Duplicates on Student_ID to remove the duplicate row
A8: 7. Build a 'Clean Summary' table next to the data using COUNTIF to count each platform
A10: Student_ID | B10: Age | C10: Gender | D10: Academic_Level | E10: Country | F10: Avg_Daily_Usage_Hours
A11: =VALUE(TRIM("232")) -> 232 | B11: 21 | C11: =PROPER("MALE") -> Male | D11: =PROPER("Undergraduate") -> Undergraduate | E11: =PROPER("Other") -> Other | F11: =VALUE(TRIM("4.0")) -> 4
A12: =VALUE(TRIM("564")) -> 564 | B12: 23 | C12: =PROPER("Female") -> Female | D12: =PROPER("UNDERGRADUATE") -> Undergraduate | E12: =PROPER("Other") -> Other | F12: =VALUE(TRIM("1.6")) -> 1.6
A13: =VALUE(TRIM("788")) -> 788 | B13: 22 | C13: =PROPER("male") -> Male | D13: =PROPER("Graduate") -> Graduate | E13: =PROPER("canada") -> Canada | F13: =VALUE(TRIM("4.6")) -> 4.6
A14: =VALUE(TRIM("686")) -> 686 | B14: 18 | C14: =PROPER("Male") -> Male | D14: =PROPER("undergraduate") -> Undergraduate | E14: =PROPER("Other") -> Other | F14: =VALUE(TRIM("7")) -> 7
A15: =VALUE(TRIM("608")) -> 608 | B15: 24 | C15: =PROPER("FEMALE") -> Female | D15: =PROPER("High School") -> High School | E15: =PROPER("other") -> Other | F15: =VALUE(TRIM("7.5")) -> 7.5
A16: =VALUE(TRIM("370")) -> 370 | B16: 23 | C16: =PROPER("Female") -> Female | D16: =PROPER("Undergraduate") -> Undergraduate | E16: =PROPER("Other") -> Other | F16: =VALUE(TRIM("1.6")) -> 1.6
A17: =VALUE(TRIM("862")) -> 862 | B17: 19 | C17: =PROPER("female") -> Female | D17: =PROPER("high school") -> High School | E17: =PROPER("Other") -> Other | F17: =VALUE(TRIM("4.1")) -> 4.1
A18: =VALUE(TRIM("520")) -> 520 | B18: 22 | C18: =PROPER("Female") -> Female | D18: =PROPER("GRADUATE") -> Graduate | E18: =PROPER("Other") -> Other | F18: =VALUE(TRIM("8.0")) -> 8
A19: =VALUE(TRIM("703")) -> 703 | B19: 21 | C19: =PROPER("Female") -> Female | D19: =PROPER("Graduate") -> Graduate | E19: =PROPER("Other") -> Other | F19: =VALUE(TRIM("6")) -> 6
A20: =VALUE(TRIM("702")) -> 702 | B20: 24 | C20: =PROPER("Male") -> Male | D20: =PROPER("Undergraduate") -> Undergraduate | E20: =PROPER("USA") -> Usa | F20: =VALUE(TRIM("4.7")) -> 4.7

Sheet Project 10 
A1: TASKS
A2: 1. Use IF to classify students: Usage > 6 hrs = 'High User', else 'Moderate User'
A3: 2. Use IF + AND: flag students where Usage > 5 AND Affects_Academic = 'Yes' as 'At Risk'
A4: 3. Use IF + OR: identify students from 'USA' OR 'Canada' as 'North America', else 'Other'
A5: 4. Use Nested IF on Mental_Health_Score: ≥7='Healthy', ≥5='Moderate', else='Low'
A6: 5. Use IFERROR to protect a division formula (e.g. Sleep_Hours / Usage) from errors
A7: 6. Use IFS to assign Sleep Bands: ≥8='Excellent', ≥6='Good', ≥4='Fair', else='Poor'
A8: 7. Count how many students are 'At Risk' using COUNTIF on your new flag column
A14: Student_ID | B14: Age | C14: Gender | D14: Academic_Level | E14: Country | F14: Avg_Daily_Usage_Hours | G14: Most_Used_Platform | H14: Affects_Academic | I14: Sleep_Hours | J14: Mental_Health_Score | K14: Overall_Impact | L14: Division formula | M14: SleepBands | N14: Flagged Students (Affects Academic ) | O14: Mental State | P14: Classification Students
A15: 232 | B15: 21 | C15: Male | D15: Undergraduate | E15: Other | F15: 4 | G15: Facebook | H15: No | I15: 6.7 | J15: 6.8 | K15: Neutral | L15: =IFERROR(I15/F15,"ERROR") -> 1.675 | M15: {=_xlfn.IFS(I15>=8,"Excellent",I15>=6,"Good",I15>=4,"Fair",I15>=0,"Poor")} -> Good | N15: =IF(AND(F15>5,H15="Yes"),"At Risk","Not At Risk") -> Not At Risk | O15: =IF(J15>=7,"Healthy",IF(J15>=5,"Moderate","Low")) -> Moderate | P15: =IF(F15>6,"high user ","moderate user ") -> moderate user
A16: 564 | B16: 23 | C16: Female | D16: Undergraduate | E16: Other | F16: 1.6 | G16: LinkedIn | H16: No | I16: 8.6 | J16: 7.6 | K16: Positive | L16: =IFERROR(I16/F16,"ERROR") -> 5.375 | M16: {=_xlfn.IFS(I16>=8,"Excellent",I16>=6,"Good",I16>=4,"Fair",I16>=0,"Poor")} -> Excellent | N16: =IF(AND(F16>5,H16="Yes"),"At Risk","Not At Risk") -> Not At Risk | O16: =IF(J16>=7,"Healthy",IF(J16>=5,"Moderate","Low")) -> Healthy | P16: =IF(F16>6,"high user ","moderate user ") -> moderate user
A17: 788 | B17: 22 | C17: Male | D17: Graduate | E17: North America | F17: 4.6 | G17: Instagram | H17: No | I17: 6.7 | J17: 7 | K17: Neutral | L17: =IFERROR(I17/F17,"ERROR") -> 1.4565217 | M17: {=_xlfn.IFS(I17>=8,"Excellent",I17>=6,"Good",I17>=4,"Fair",I17>=0,"Poor")} -> Good | N17: =IF(AND(F17>5,H17="Yes"),"At Risk","Not At Risk") -> Not At Risk | O17: =IF(J17>=7,"Healthy",IF(J17>=5,"Moderate","Low")) -> Healthy | P17: =IF(F17>6,"high user ","moderate user ") -> moderate user
A18: 686 | B18: 18 | C18: Male | D18: Undergraduate | E18: Other | F18: 7 | G18: Snapchat | H18: Yes | I18: 5.4 | J18: 5.3 | K18: Negative | L18: =IFERROR(I18/F18,"ERROR") -> 0.77142857 | M18: {=_xlfn.IFS(I18>=8,"Excellent",I18>=6,"Good",I18>=4,"Fair",I18>=0,"Poor")} -> Fair | N18: =IF(AND(F18>5,H18="Yes"),"At Risk","Not At Risk") -> At Risk | O18: =IF(J18>=7,"Healthy",IF(J18>=5,"Moderate","Low")) -> Moderate | P18: =IF(F18>6,"high user ","moderate user ") -> high user
A19: 608 | B19: 24 | C19: Female | D19: High School | E19: Other | F19: 7.5 | G19: Facebook | H19: Yes | I19: 5 | J19: 4.4 | K19: Negative | L19: =IFERROR(I19/F19,"ERROR") -> 0.66666667 | M19: {=_xlfn.IFS(I19>=8,"Excellent",I19>=6,"Good",I19>=4,"Fair",I19>=0,"Poor")} -> Fair | N19: =IF(AND(F19>5,H19="Yes"),"At Risk","Not At Risk") -> At Risk | O19: =IF(J19>=7,"Healthy",IF(J19>=5,"Moderate","Low")) -> Low | P19: =IF(F19>6,"high user ","moderate user ") -> high user
A20: 370 | B20: 19 | C20: Female | D20: High School | E20: Other | F20: 4.1 | G20: /. | H20: Yes | I20: 6.8 | J20: 6.8 | K20: Neutral | L20: =IFERROR(I20/F20,"ERROR") -> 1.6585366 | M20: {=_xlfn.IFS(I20>=8,"Excellent",I20>=6,"Good",I20>=4,"Fair",I20>=0,"Poor")} -> Good | N20: =IF(AND(F20>5,H20="Yes"),"At Risk","Not At Risk") -> Not At Risk | O20: =IF(J20>=7,"Healthy",IF(J20>=5,"Moderate","Low")) -> Moderate | P20: =IF(F20>6,"high user ","moderate user ") -> moderate user
A21: 862 | B21: 22 | C21: Female | D21: Graduate | E21: Other | F21: 8 | G21: Instagram | H21: Yes | I21: 5.2 | J21: 5.3 | K21: Negative | L21: =IFERROR(I21/F21,"ERROR") -> 0.65 | M21: {=_xlfn.IFS(I21>=8,"Excellent",I21>=6,"Good",I21>=4,"Fair",I21>=0,"Poor")} -> Fair | N21: =IF(AND(F21>5,H21="Yes"),"At Risk","Not At Risk") -> At Risk | O21: =IF(J21>=7,"Healthy",IF(J21>=5,"Moderate","Low")) -> Moderate | P21: =IF(F21>6,"high user ","moderate user ") -> high user
A22: 520 | B22: 21 | C22: Female | D22: Graduate | E22: Other | F22: 6 | G22: Facebook | H22: Yes | I22: 5.7 | J22: 4.7 | K22: Negative | L22: =IFERROR(I22/F22,"ERROR") -> 0.95 | M22: {=_xlfn.IFS(I22>=8,"Excellent",I22>=6,"Good",I22>=4,"Fair",I22>=0,"Poor")} -> Fair | N22: =IF(AND(F22>5,H22="Yes"),"At Risk","Not At Risk") -> At Risk | O22: =IF(J22>=7,"Healthy",IF(J22>=5,"Moderate","Low")) -> Low | P22: =IF(F22>6,"high user ","moderate user ") -> moderate user
A23: 703 | B23: 24 | C23: Male | D23: Undergraduate | E23: North America | F23: 4.7 | G23: YouTube | H23: No | I23: 7 | J23: 6.2 | K23: Neutral | L23: =IFERROR(I23/F23,"ERROR") -> 1.4893617 | M23: {=_xlfn.IFS(I23>=8,"Excellent",I23>=6,"Good",I23>=4,"Fair",I23>=0,"Poor")} -> Good | N23: =IF(AND(F23>5,H23="Yes"),"At Risk","Not At Risk") -> Not At Risk | O23: =IF(J23>=7,"Healthy",IF(J23>=5,"Moderate","Low")) -> Moderate | P23: =IF(F23>6,"high user ","moderate user ") -> moderate user
A24: 33 | B24: 19 | C24: Male | D24: High School | E24: Other | F24: 3.6 | G24: TikTok | H24: No | I24: 8.1 | J24: 8.6 | K24: Positive | L24: =IFERROR(I24/F24,"ERROR") -> 2.25 | M24: {=_xlfn.IFS(I24>=8,"Excellent",I24>=6,"Good",I24>=4,"Fair",I24>=0,"Poor")} -> Excellent | N24: =IF(AND(F24>5,H24="Yes"),"At Risk","Not At Risk") -> Not At Risk | O24: =IF(J24>=7,"Healthy",IF(J24>=5,"Moderate","Low")) -> Healthy | P24: =IF(F24>6,"high user ","moderate user ") -> moderate user
A25: 519 | B25: 18 | C25: Male | D25: Graduate | E25: Other | F25: 4.1 | G25: LinkedIn | H25: No | I25: 7.3 | J25: 6.8 | K25: Neutral | L25: =IFERROR(I25/F25,"ERROR") -> 1.7804878 | M25: {=_xlfn.IFS(I25>=8,"Excellent",I25>=6,"Good",I25>=4,"Fair",I25>=0,"Poor")} -> Good | N25: =IF(AND(F25>5,H25="Yes"),"At Risk","Not At Risk") -> Not At Risk | O25: =IF(J25>=7,"Healthy",IF(J25>=5,"Moderate","Low")) -> Moderate | P25: =IF(F25>6,"high user ","moderate user ") -> moderate user
A26: 738 | B26: 18 | C26: Male | D26: High School | E26: Other | F26: 7.6 | G26: Snapchat | H26: Yes | I26: 5.3 | J26: 5.5 | K26: Negative | L26: =IFERROR(I26/F26,"ERROR") -> 0.69736842 | M26: {=_xlfn.IFS(I26>=8,"Excellent",I26>=6,"Good",I26>=4,"Fair",I26>=0,"Poor")} -> Fair | N26: =IF(AND(F26>5,H26="Yes"),"At Risk","Not At Risk") -> At Risk | O26: =IF(J26>=7,"Healthy",IF(J26>=5,"Moderate","Low")) -> Moderate | P26: =IF(F26>6,"high user ","moderate user ") -> high user
... A34: 631 | B34: 20 | C34: Male | D34: Undergraduate | E34: Other | F34: 5.5 | G34: Instagram | H34: No | I34: 6.8 | J34: 6.8 | K34: Neutral | L34: =IFERROR(I34/F34,"ERROR") -> 1.2363636 | M34: {=_xlfn.IFS(I34>=8,"Excellent",I34>=6,"Good",I34>=4,"Fair",I34>=0,"Poor")} -> Good | N34: =IF(AND(F34>5,H34="Yes"),"At Risk","Not At Risk") -> Not At Risk | O34: =IF(J34>=7,"Healthy",IF(J34>=5,"Moderate","Low")) -> Moderate | P34: =IF(F34>6,"high user ","moderate user ") -> moderate user
A35: Total Students At Risk | B35: =COUNTIF(N15:N35,N21) -> 9

Sheet Project 11
A4: EmpID | B4: Name | C4: Department | D4: Salary | E4: Salary_Band | F4: Job Title | G4: Email | H4: Tenure
A5: 1001 | B5: Jim Halpert | C5: Sales | D5: 45000 | E5: =VLOOKUP(D5,$A$4:$H$14,4,1) -> 58000 | F5: Salesman | G5: jim@dm.com | H5: 13
A6: 1002 | B6: Pam Beasley | C6: Admin | D6: 36000 | E6: =VLOOKUP(D6,$A$4:$H$14,4,1) -> 58000 | F6: Receptionist | G6: pam@dm.com | H6: 16
A7: 1003 | B7: Dwight Schrute | C7: Sales | D7: 63000 | E7: =VLOOKUP(D7,$A$4:$H$14,4,1) -> 58000 | F7: Asst RM | G7: dwight@aol.com | H7: 17
A8: 1004 | B8: Angela Martin | C8: Accounting | D8: 47000 | E8: =VLOOKUP(D8,$A$4:$H$14,4,1) -> 58000 | F8: Accountant | G8: angela@dm.com | H8: 15
A9: 1005 | B9: Toby Flenderson | C9: HR | D9: 50000 | E9: =VLOOKUP(D9,$A$4:$H$14,4,1) -> 58000 | F9: HR Rep | G9: toby@dm.com | H9: 16
A10: 1006 | B10: Michael Scott | C10: Management | D10: 65000 | E10: =VLOOKUP(D10,$A$4:$H$14,4,1) -> 58000 | F10: Regional Mgr | G10: michael@dm.com | H10: 12
A11: 1007 | B11: Meredith Palmer | C11: Supply | D11: 55000 | E11: =VLOOKUP(D11,$A$4:$H$14,4,1) -> 58000 | F11: Supplier Rel | G11: meredith@yahoo.com | H11: 9
A12: 1008 | B12: Stanley Hudson | C12: Sales | D12: 48000 | E12: =VLOOKUP(D12,$A$4:$H$14,4,1) -> 58000 | F12: Salesman | G12: stanley@gmail.com | H12: 12
A13: 1009 | B13: Kevin Malone | C13: Accounting | D13: 52000 | E13: =VLOOKUP(D13,$A$4:$H$14,4,1) -> 58000 | F13: Accountant | G13: kevin@dm.com | H13: 11
A14: 1010 | B14: Oscar Martinez | C14: Accounting | D14: 58000 | E14: =VLOOKUP(D14,$A$4:$H$14,4,1) -> 58000 | F14: Sr Accountant | G14: oscar@dm.com | H14: 13
A20: 1. Use VLOOKUP to retrieve Name, Department, and Salary for EmpIDs: 1005, 1008
A21: Emp_ID | B21: Name | C21: Dept | D21: Salary
A22: 1005 | B22: =VLOOKUP($A22,'Project 11'!$A$4:$H$14,2,0) -> Toby Flenderson | C22: =VLOOKUP($A22,'Project 11'!$A$4:$H$14,3,0) -> HR | D22: =VLOOKUP($A22,'Project 11'!$A$4:$H$14,4,0) -> 50000
A23: 1008 | B23: =VLOOKUP(A23,'Project 11'!$A$4:$H$14,2,0) -> Stanley Hudson | C23: =VLOOKUP($A23,'Project 11'!$A$4:$H$14,3,0) -> Sales | D23: =VLOOKUP($A23,'Project 11'!$A$4:$H$14,4,0) -> 48000
A28: 2. Use INDEX+MATCH to retrieve the same data — compare results with VLOOKUP
A29: Emp_ID | B29: Name | C29: Dept | D29: Salary
A30: 1005 | B30: {=INDEX('Project 11'!$A$4:$H$14,MATCH('Project 11'!$A$9,'Project 11'!$A$4:$A$14,0),2)} -> Toby Flenderson | C30: {=INDEX('Project 11'!$A$4:$H$14,MATCH('Project 11'!$A$9,'Project 11'!$A$4:$A$14,0),3)} -> HR | D30: {=INDEX('Project 11'!$A$4:$H$14,MATCH('Project 11'!$A$9,'Project 11'!$A$4:$A$14,0),4)} -> 50000
A31: 1008 | B31: {=INDEX('Project 11'!$A$4:$H$14,MATCH('Project 11'!$A$12,'Project 11'!$A$4:$A$14,0),2)} -> Stanley Hudson | C31: {=INDEX('Project 11'!$A$4:$H$14,MATCH('Project 11'!$A$12,'Project 11'!$A$4:$A$14,0),3)} -> Sales | D31: {=INDEX('Project 11'!$A$4:$H$14,MATCH('Project 11'!$A$12,'Project 11'!$A$4:$A$14,0),4)} -> 48000
A37: 3. Use VLOOKUP with IFERROR to handle a lookup for EmpID 9999 (doesn't exist)
A38: Emp_ID | B38: Name | C38: Dept | D38: Salary
A39: 1005 | B39: =VLOOKUP($A39,'Project 11'!$A$4:$H$14,2,0) -> Toby Flenderson | C39: =VLOOKUP($A39,'Project 11'!$A$4:$H$14,3,0) -> HR | D39: =VLOOKUP($A39,'Project 11'!$A$4:$H$14,4,0) -> 50000
A40: 1008 | B40: =VLOOKUP(A40,'Project 11'!$A$4:$H$14,2,0) -> Stanley Hudson | C40: =VLOOKUP($A40,'Project 11'!$A$4:$H$14,3,0) -> Sales | D40: =VLOOKUP($A40,'Project 11'!$A$4:$H$14,4,0) -> 48000
A41: 9999 | B41: =IFERROR(VLOOKUP(A41,'Project 11'!$A$4:$H$14,2,0),"ERROR") -> ERROR | C41: =IFERROR(VLOOKUP(A41,'Project 11'!$A$4:$H$14,3,0),"ERROR") -> ERROR | D41: =IFERROR(VLOOKUP(A41,'Project 11'!$A$4:$H$14,4,0),"ERROR") -> ERROR
A45: 4. Build a 2-way INDEX+MATCH to find Salary given both EmpID and column header
A46: Emp_ID | B46: Name | C46: Dept | D46: Salary
A47: 1008 | B47: {=INDEX('Project 11'!$A$5:$H$14,MATCH($A47,'Project 11'!$A$5:$A$14,0),2)} -> Stanley Hudson | C47: {=INDEX('Project 11'!$A$5:$H$14,MATCH($A47,'Project 11'!$A$5:$A$14,0),3)} -> Sales | D47: {=INDEX('Project 11'!$A$5:$H$14,MATCH($A47,'Project 11'!$A$5:$A$14,0),4)} -> 48000
A48: 1005 | B48: {=INDEX('Project 11'!$A$5:$H$14,MATCH($A48,'Project 11'!$A$5:$A$14,0),2)} -> Toby Flenderson | C48: {=INDEX('Project 11'!$A$5:$H$14,MATCH($A48,'Project 11'!$A$5:$A$14,0),3)} -> HR | D48: {=INDEX('Project 11'!$A$5:$H$14,MATCH($A48,'Project 11'!$A$5:$A$14,0),4)} -> 50000
A54: 5. Add a new column 'Salary Band': use VLOOKUP with approximate match on a lookup table
A55: EmpID | B55: Name | C55: Department | D55: Salary | E55: Salary_Band | F55: Job Title | G55: Email | H55: Tenure
A56: 1001 | B56: Jim Halpert | C56: Sales | D56: 45000 | E56: =VLOOKUP(D56,$A$4:$H$14,4,1) -> 58000 | F56: Salesman | G56: jim@dm.com | H56: 13
A57: 1002 | B57: Pam Beasley | C57: Admin | D57: 36000 | E57: =VLOOKUP(D57,$A$4:$H$14,4,1) -> 58000 | F57: Receptionist | G57: pam@dm.com | H57: 16
A58: 1003 | B58: Dwight Schrute | C58: Sales | D58: 63000 | E58: =VLOOKUP(D58,$A$4:$H$14,4,1) -> 58000 | F58: Asst RM | G58: dwight@aol.com | H58: 17
A59: 1004 | B59: Angela Martin | C59: Accounting | D59: 47000 | E59: =VLOOKUP(D59,$A$4:$H$14,4,1) -> 58000 | F59: Accountant | G59: angela@dm.com | H59: 15
A60: 1005 | B60: Toby Flenderson | C60: HR | D60: 50000 | E60: =VLOOKUP(D60,$A$4:$H$14,4,1) -> 58000 | F60: HR Rep | G60: toby@dm.com | H60: 16
A61: 1006 | B61: Michael Scott | C61: Management | D61: 65000 | E61: =VLOOKUP(D61,$A$4:$H$14,4,1) -> 58000 | F61: Regional Mgr | G61: michael@dm.com | H61: 12
A62: 1007 | B62: Meredith Palmer | C62: Supply | D62: 55000 | E62: =VLOOKUP(D62,$A$4:$H$14,4,1) -> 58000 | F62: Supplier Rel | G62: meredith@yahoo.com | H62: 9
A63: 1008 | B63: Stanley Hudson | C63: Sales | D63: 48000 | E63: =VLOOKUP(D63,$A$4:$H$14,4,1) -> 58000 | F63: Salesman | G63: stanley@gmail.com | H63: 12
A64: 1009 | B64: Kevin Malone | C64: Accounting | D64: 52000 | E64: =VLOOKUP(D64,$A$4:$H$14,4,1) -> 58000 | F64: Accountant | G64: kevin@dm.com | H64: 11
A65: 1010 | B65: Oscar Martinez | C65: Accounting | D65: 58000 | E65: =VLOOKUP(D65,$A$4:$H$14,4,1) -> 58000 | F65: Sr Accountant | G65: oscar@dm.com | H65: 13
...

Sheet Project 12
A1: TASKS
A2: 1. Apply AutoFilter to the dataset — filter by Gender='Female' and check SUBTOTAL updates
A3: 2. Filter by Overall_Impact='Negative' — note how SUBTOTAL(9) sum changes
A8: Student_ID | B8: Age | C8: Gender | D8: Academic_Level | E8: Country | F8: Avg_Daily_Usage_Hours | G8: Most_Used_Platform | H8: Affects_Academic | I8: Sleep_Hours | J8: Mental_Health_Score | K8: Comparison | L8: Sub Total | M8: Overall_Impact
A9: 232 | B9: 21 | C9: Male | D9: Undergraduate | E9: Other | F9: 4 | G9: Facebook | H9: No | I9: 6.7 | J9: 6.8 | L9: =SUBTOTAL(2,$A$9:$A$28) -> 20 | M9: Neutral
A10: 564 | B10: 23 | C10: Female | D10: Undergraduate | E10: Other | F10: 1.6 | G10: LinkedIn | H10: No | I10: 8.6 | J10: 7.6 | M10: Positive
A11: 788 | B11: 22 | C11: Male | D11: Graduate | E11: Canada | F11: 4.6 | G11: Instagram | H11: No | I11: 6.7 | J11: 7 | M11: Neutral
A12: 686 | B12: 18 | C12: Male | D12: Undergraduate | E12: Other | F12: 7 | G12: Snapchat | H12: Yes | I12: 5.4 | J12: 5.3 | M12: Negative
A13: 608 | B13: 24 | C13: Female | D13: High School | E13: Other | F13: 7.5 | G13: Facebook | H13: Yes | I13: 5 | J13: 4.4 | M13: Negative
A14: 370 | B14: 19 | C14: Female | D14: High School | E14: Other | F14: 4.1 | G14: Twitter | H14: Yes | I14: 6.8 | J14: 6.8 | M14: Neutral
A15: 862 | B15: 22 | C15: Female | D15: Graduate | E15: Other | F15: 8 | G15: Instagram | H15: Yes | I15: 5.2 | J15: 5.3 | M15: Negative
A16: 520 | B16: 21 | C16: Female | D16: Graduate | E16: Other | F16: 6 | G16: Facebook | H16: Yes | I16: 5.7 | J16: 4.7 | M16: Negative
A17: 703 | B17: 24 | C17: Male | D17: Undergraduate | E17: USA | F17: 4.7 | G17: YouTube | H17: No | I17: 7 | J17: 6.2 | M17: Neutral
A18: 33 | B18: 19 | C18: Male | D18: High School | E18: Other | F18: 3.6 | G18: TikTok | H18: No | I18: 8.1 | J18: 8.6 | M18: Positive
A19: 519 | B19: 18 | C19: Male | D19: Graduate | E19: Other | F19: 4.1 | G19: LinkedIn | H19: No | I19: 7.3 | J19: 6.8 | M19: Neutral
A20: 738 | B20: 18 | C20: Male | D20: High School | E20: Other | F20: 7.6 | G20: Snapchat | H20: Yes | I20: 5.3 | J20: 5.5 | M20: Negative
A21: 119 | B21: 20 | C21: Male | D21: Undergraduate | E21: Other | F21: 2.4 | G21: Facebook | H21: No | I21: 8.8 | J21: 8.5 | M21: Positive
... A28: 631 | B28: 20 | C28: Male | D28: Undergraduate | E28: Other | F28: 5.5 | G28: Instagram | H28: No | I28: 6.8 | J28: 6.8 | M28: Neutral
A30: SUBTOTAL SUMMARY (updates when you filter the table above)
A31: Metric | B31: Function | C31: Formula | D31: Result (visible rows) | E31: Notes
A32: Count of students | B32: =SUBTOTAL(3,$C$9:$C$28) -> 20 | C32: =SUBTOTAL(3,$A$9:$A$28) -> 20 | D32: =SUBTOTAL(3,$A$9:$A$28) -> 20 | E32: Count rows visible
A33: Avg Daily Usage | B33: =SUBTOTAL(1,$F$9:$F$28) -> 5.25 | C33: =SUBTOTAL(1,$F$9:$F$28) -> 5.25 | D33: =SUBTOTAL(1,$F$9:$F$28) -> 5.25 | E33: Avg usage (visible)
A34: Total Usage Hours | B34: =SUBTOTAL(9,$F$9:$F$28) -> 105 | C34: =SUBTOTAL(9,$F$9:$F$28) -> 105 | D34: =SUBTOTAL(9,$F$9:$F$28) -> 105 | E34: Sum (visible)
A35: Max Mental Health | B35: =SUBTOTAL(4,$J$9:$J$28) -> 8.6 | C35: =SUBTOTAL(4,$I$9:$I$28) -> 8.8 | D35: =SUBTOTAL(4,$I$9:$I$28) -> 8.8 | E35: Max score
A36: Min Sleep Hours | B36: =SUBTOTAL(5,$I$9:$I$28) -> 5 | C36: =SUBTOTAL(5,$H$9:$H$28) -> 0 | D36: =SUBTOTAL(5,$H$9:$H$28) -> 0 | E36: Min sleep
A37: Avg Sleep Hours | B37: =SUBTOTAL(1,'Project 12'!$I$9:$I$28) -> 6.565 | C37: =SUBTOTAL(1,'Project 12'!$H$9:$H$28) -> #DIV/0! | D37: =SUBTOTAL(1,'Project 12'!$H$9:$H$28) -> #DIV/0! | E37: Avg sleep
A38: 6. Use SUBTOTAL(3,...) to count students by platform (filter each platform and observe)
A39: 7. Compare SUBTOTAL(9,...) vs SUM(...) on the same column — filter and observe the difference
A44: 3. Use INDEX+MATCH to find the Student_ID of the student with the highest Mental_Health_Score
A45: Student_ID | B45: Mental_Health_Score
A46: =LOOKUP('Project 12'!$J$18,'Project 12'!$J$9:$J$28,'Project 12'!$A$9:$A$28) -> 33 | B46: =LARGE('Project 12'!$J$9:$J$28,1) -> 8.6
A55: 4. Use INDEX+MATCH to find the Platform used by the student with the most daily usage
A56: Most Daily Usage | B56: Platform | C56: Student
A57: =LARGE('Project 12'!$F$9:$F$28,1) -> 8 | B57: =LOOKUP('Project 12'!$F$15,'Project 12'!$F$9:$F$28,'Project 12'!$G$9:$G$28) -> Instagram | C57: {=INDEX('Project 12'!$A$8:$M$28,MATCH('Project 12'!$F$15,'Project 12'!$F$8:$F$28,0),1)} -> 862
A68: 5. Build a two-way INDEX+MATCH to retrieve a value from a specific row and column
A69: Row | B69: Column | C69: Result
A70: 564 | B70: Avg_Daily_Usage_Hours | C70: {=INDEX('Project 12'!A8:M28,MATCH(A70,'Project 12'!A8:A28,0),MATCH(B70,'Project 12'!A8:M8,0))} -> 1.6

Sheet Project 13
A1: TASKS — BUILD THESE PIVOT TABLES ON NEW SHEETS
A2: 1. Create a Pivot Table: Rows = Most_Used_Platform, Values = COUNT of Student_ID
A3: 2. Create a Pivot Table: Rows = Overall_Impact, Values = AVERAGE Mental_Health_Score
A4: 3. Create a Pivot Table: Rows = Academic_Level, Columns = Gender, Values = COUNT Student_ID
A5: 4. Create a Pivot Table: Rows = Affects_Academic, Values = AVERAGE Avg_Daily_Usage_Hours
A6: 5. Add a Pivot Chart (clustered column) to your platform count pivot
A7: 6. Sort each pivot by value — largest to smallest
A8: 7. Add a calculated field: 'Sleep Deficit' = 8 - Sleep_Hours_Per_Night (PivotTable Analyze > Fields, Items & Sets)
A12: Student_ID | B12: Age | C12: Gender | D12: Academic_Level | E12: Country | F12: Avg_Daily_Usage_Hours | G12: Most_Used_Platform | H12: Affects_Academic | I12: Sleep_Hours | J12: Mental_Health_Score | K12: Sleep Deficit | L12: Overall_Impact
A13: 232 | B13: 21 | C13: Male | D13: Undergraduate | E13: Other | F13: 4 | G13: Facebook | H13: No | I13: 6.7 | J13: 6.8 | K13: =8-I13 -> 1.3 | L13: Neutral
A14: 564 | B14: 23 | C14: Female | D14: Undergraduate | E14: Other | F14: 1.6 | G14: LinkedIn | H14: No | I14: 8.6 | J14: 7.6 | K14: =8-I14 -> -0.6 | L14: Positive
A15: 788 | B15: 22 | C15: Male | D15: Graduate | E15: Canada | F15: 4.6 | G15: Instagram | H15: No | I15: 6.7 | J15: 7 | K15: =8-I15 -> 1.3 | L15: Neutral
A16: 686 | B16: 18 | C16: Male | D16: Undergraduate | E16: Other | F16: 7 | G16: Snapchat | H16: Yes | I16: 5.4 | J16: 5.3 | K16: =8-I16 -> 2.6 | L16: Negative
A17: 608 | B17: 24 | C17: Female | D17: High School | E17: Other | F17: 7.5 | G17: Facebook | H17: Yes | I17: 5 | J17: 4.4 | K17: =8-I17 -> 3 | L17: Negative
A18: 370 | B18: 19 | C18: Female | D18: High School | E18: Other | F18: 4.1 | G18: Twitter | H18: Yes | I18: 6.8 | J18: 6.8 | K18: =8-I18 -> 1.2 | L18: Neutral
A19: 862 | B19: 22 | C19: Female | D19: Graduate | E19: Other | F19: 8 | G19: Instagram | H19: Yes | I19: 5.2 | J19: 5.3 | K19: =8-I19 -> 2.8 | L19: Negative
A20: 520 | B20: 21 | C20: Female | D20: Graduate | E20: Other | F20: 6 | G20: Facebook | H20: Yes | I20: 5.7 | J20: 4.7 | K20: =8-I20 -> 2.3 | L20: Negative
A21: 703 | B21: 24 | C21: Male | D21: Undergraduate | E21: USA | F21: 4.7 | G21: YouTube | H21: No | I21: 7 | J21: 6.2 | K21: =8-I21 -> 1 | L21: Neutral
A22: 33 | B22: 19 | C22: Male | D22: High School | E22: Other | F22: 3.6 | G22: TikTok | H22: No | I22: 8.1 | J22: 8.6 | K22: =8-I22 -> -0.1 | L22: Positive
A23: 519 | B23: 18 | C23: Male | D23: Graduate | E23: Other | F23: 4.1 | G23: LinkedIn | H23: No | I23: 7.3 | J23: 6.8 | K23: =8-I23 -> 0.7 | L23: Neutral
A24: 738 | B24: 18 | C24: Male | D24: High School | E24: Other | F24: 7.6 | G24: Snapchat | H24: Yes | I24: 5.3 | J24: 5.5 | K24: =8-I24 -> 2.7 | L24: Negative
... A32: 631 | B32: 20 | C32: Male | D32: Undergraduate | E32: Other | F32: 5.5 | G32: Instagram | H32: No | I32: 6.8 | J32: 6.8 | K32: =8-I32 -> 1.2 | L32: Neutral
A35: Most_Used_Platform | B35: Count of Student_ID | G35: Overall_Impact | H35: Average of Mental_Health_Score
A36: YouTube | B36: 3 | G36: Positive | H36: 8.125
A37: Twitter | B37: 2 | G37: Neutral | H37: 6.6714286
A38: TikTok | B38: 1 | G38: Negative | H38: 5.0666667
A39: Snapchat | B39: 2 | G39: Grand Total | H39: 6.24
A40: LinkedIn | B40: 3
A41: Instagram | B41: 4
A42: Facebook | B42: 5
A43: Grand Total | B43: 20
A55: Count of Student_ID | B55: Gender | H55: Gender | I55: Count of Most_Used_Platform
A56: Academic_Level | B56: Male | C56: Female | D56: Grand Total | H56: Male | I56: 12
A57: Undergraduate | B57: 5 | C57: 2 | D57: 7 | H57: Female | I57: 8
A58: High School | B58: 3 | C58: 2 | D58: 5 | H58: Grand Total | I58: 20
A59: Graduate | B59: 4 | C59: 4 | D59: 8
A60: Grand Total | B60: 12 | C60: 8 | D60: 20
A77: Affects_Academic | B77: Average of Avg_Daily_Usage_Hours
A78: Yes | B78: 6.56
A79: No | B79: 3.94
...

Sheet Project 14 
A1: TASKS
A2: 1. Insert a Slicer on 'Gender' and connect it to all pivot tables on this workbook
A3: 2. Insert a Slicer on 'Overall_Impact' — use it to filter to 'Negative' students only
A4: 3. Group the Age field into bands: 18-20, 21-22, 23-24
A5: 4. Create a pivot chart (Bar) for platform counts — format with chart title and data labels
A6: 5. Create a pie chart pivot for Overall_Impact distribution
A7: 6. Build a mini-dashboard: place 3 pivot charts + 2 slicers on one sheet
A8: 7. Apply a consistent colour theme to all charts on your dashboard sheet
A12: Student_ID | B12: Age | C12: Gender | D12: Academic_Level | E12: Country | F12: Avg_Daily_Usage_Hours | G12: Most_Used_Platform | H12: Affects_Academic | I12: Sleep_Hours | J12: Mental_Health_Score | K12: Overall_Impact
A13: 232 | B13: 21 | C13: Male | D13: Undergraduate | E13: Other | F13: 4 | G13: Facebook | H13: No | I13: 6.7 | J13: 6.8 | K13: Neutral
A14: 564 | B14: 23 | C14: Female | D14: Undergraduate | E14: Other | F14: 1.6 | G14: LinkedIn | H14: No | I14: 8.6 | J14: 7.6 | K14: Positive
A15: 788 | B15: 22 | C15: Male | D15: Graduate | E15: Canada | F15: 4.6 | G15: Instagram | H15: No | I15: 6.7 | J15: 7 | K15: Neutral
A16: 686 | B16: 18 | C16: Male | D16: Undergraduate | E16: Other | F16: 7 | G16: Snapchat | H16: Yes | I16: 5.4 | J16: 5.3 | K16: Negative
A17: 608 | B17: 24 | C17: Female | D17: High School | E17: Other | F17: 7.5 | G17: Facebook | H17: Yes | I17: 5 | J17: 4.4 | K17: Negative
A18: 370 | B18: 19 | C18: Female | D18: High School | E18: Other | F18: 4.1 | G18: Twitter | H18: Yes | I18: 6.8 | J18: 6.8 | K18: Neutral
A19: 862 | B19: 22 | C19: Female | D19: Graduate | E19: Other | F19: 8 | G19: Instagram | H19: Yes | I19: 5.2 | J19: 5.3 | K19: Negative
A20: 520 | B20: 21 | C20: Female | D20: Graduate | E20: Other | F20: 6 | G20: Facebook | H20: Yes | I20: 5.7 | J20: 4.7 | K20: Negative
A21: 703 | B21: 24 | C21: Male | D21: Undergraduate | E21: USA | F21: 4.7 | G21: YouTube | H21: No | I21: 7 | J21: 6.2 | K21: Neutral
A22: 33 | B22: 19 | C22: Male | D22: High School | E22: Other | F22: 3.6 | G22: TikTok | H22: No | I22: 8.1 | J22: 8.6 | K22: Positive
A23: 519 | B23: 18 | C23: Male | D23: Graduate | E23: Other | F23: 4.1 | G23: LinkedIn | H23: No | I23: 7.3 | J23: 6.8 | K23: Neutral
A24: 738 | B24: 18 | C24: Male | D24: High School | E24: Other | F24: 7.6 | G24: Snapchat | H24: Yes | I24: 5.3 | J24: 5.5 | K24: Negative
... A32: 631 | B32: 20 | C32: Male | D32: Undergraduate | E32: Other | F32: 5.5 | G32: Instagram | H32: No | I32: 6.8 | J32: 6.8 | K32: Neutral
A39: Overall_Impact | B39: Count of Student_ID | E39: Age | F39: Count of Student_ID
A40: Negative | B40: 9 | E40: 18-20 | F40: 2
A41: Grand Total | B41: 9 | E41: 21-24 | F41: 7
E42: Grand Total | F42: 9
A55: Country | B55: Count of Most_Used_Platform
A56: Australia | B56: 1
A57: Canada | B57: 2
A58: India | B58: 1
A59: Grand Total | B59: 4
A73: Overall_Impact | B73: Count of Most_Used_Platform
A74: Neutral | B74: 7
A75: Negative | B75: 9
A76: Grand Total | B76: 16

Sheet Dash Board 

Sheet Project 15
A1: CAPSTONE MARKING CRITERIA
A2: ✅ Phase 1 (20pts): All data cleaned — no extra spaces, consistent case, no duplicate IDs
A3: ✅ Phase 2 (20pts): Usage Band, Sleep Band, Risk Flag, and Age Group columns all correct
A4: ✅ Phase 3 (20pts): Summary table shows correct SUMIF/COUNTIF/AVERAGEIF per group
A5: ✅ Phase 4 (15pts): Student Card auto-fills when you change Student_ID in C15
A6: ✅ Phase 5 (15pts): 4+ properly labelled charts with titles, axis labels, and data labels
A7: ✅ Phase 6 (10pts): Dashboard has slicers, consistent colours, and clear KPI summaries
A8: 🎯 Bonus: Add a conditional format to highlight 'AT RISK' students in Red on the data sheet
A10: Student_ID | B10: Age | C10: Gender | D10: Academic_Level | E10: Country | F10: Avg_Daily_Usage_Hours | G10: Most_Used_Platform | H10: Affects_Academic | I10: Sleep_Hours | J10: Mental_Health_Score | K10: Overall_Impact
A11: 232 | B11: 21 | C11: Male | D11: Undergraduate | E11: Other | F11: 4 | G11: Facebook | H11: No | I11: 6.7 | J11: 6.8 | K11: Neutral
A12: 564 | B12: 23 | C12: Female | D12: Undergraduate | E12: Other | F12: 1.6 | G12: LinkedIn | H12: No | I12: 8.6 | J12: 7.6 | K12: Positive
A13: 788 | B13: 22 | C13: Male | D13: Graduate | E13: Canada | F13: 4.6 | G13: Instagram | H13: No | I13: 6.7 | J13: 7 | K13: Neutral
